Workbook

Sheet Current Distribution
C3: 2019 | D3: 2020 | E3: 2021 | F3: 2022 | G3: 2023 | H3: 2024 | I3: 2025 | J3: 2026 | K3: 2027 | L3: 2028 | M3: 2029 | N3: 2030 | O3: 2031 | P3: 2032 | Q3: 2033 | R3: 2034 | S3: 2035 | T3: 2036 | U3: 2037 | V3: 2038 | W3: 2039 | X3: 2040 | Y3: 2041 | Z3: 2042 | AA3: 2043 | AB3: 2044 | AC3: 2045 | AD3: 2046 | AE3: 2047 | AF3: 2048 | AG3: 2049 | AH3: 2050 | AI3: 2051 | AJ3: 2052
A4: Age Mr. B | C4: 57 | D4: 58 | E4: 59 | F4: 60 | G4: 61 | H4: 62 | I4: 63 | J4: 64 | K4: 65 | L4: 66 | M4: 67 | N4: 68 | O4: 69 | P4: 70 | Q4: 71 | R4: 72 | S4: 73 | T4: 74 | U4: 75 | V4: 76 | W4: 77 | X4: 78 | Y4: 79 | Z4: 80 | AA4: 81 | AB4: 82 | AC4: 83 | AD4: 84 | AE4: 85 | AF4: 86 | AG4: 87 | AH4: 88 | AI4: 89 | AJ4: 90
L5: 1 | M5: 2 | N5: 3 | O5: 4 | P5: 5 | Q5: 6 | R5: 7 | S5: 8 | T5: 9 | U5: 10 | V5: 11 | W5: 12 | X5: 13 | Y5: 14 | Z5: 15 | AA5: 16 | AB5: 17 | AC5: 18 | AD5: 19 | AE5: 20 | AF5: 21 | AG5: 22 | AH5: 23 | AI5: 24 | AJ5: 25
A6: Age Mrs. B | C6: 67 | D6: 68 | E6: 69 | F6: 70 | G6: 71 | H6: 72 | I6: 73 | J6: 74 | K6: 75 | L6: 76 | M6: 77 | N6: 78 | O6: 79 | P6: 80 | Q6: 81 | R6: 82 | S6: 83 | T6: 84 | U6: 85 | V6: 86 | W6: 87 | X6: 88 | Y6: 89 | Z6: 90 | AA6: 91 | AB6: 92 | AC6: 93 | AD6: 94 | AE6: 95 | AF6: 96 | AG6: 97 | AH6: 98 | AI6: 99 | AJ6: 100
I7: Rate of Return = | J7: 1.06 | L7: Inflation | M7: 1.03 | O7: Annual Afrer Tax Income | Q7: 325000
A8: Income Source
A9: Bob's Pension | C9: 134686 | D9: 134686 | E9: 134686 | F9: 134686 | G9: 134686 | H9: 134686 | I9: 134686 | J9: 134686 | K9: 134686 | L9: 134686 | M9: 134686 | N9: 134686 | O9: 134686 | P9: 134686 | Q9: 134686 | R9: 134686 | S9: 134686 | T9: 134686 | U9: 134686 | V9: 134686 | W9: 134686 | X9: 134686 | Y9: 134686 | Z9: 134686 | AA9: 134686 | AB9: 134686 | AC9: 134686 | AD9: 134686 | AE9: 134686 | AF9: 134686 | AG9: 134686 | AH9: 134686 | AI9: 134686 | AJ9: 134686
A10: Susan's Pension | C10: 22000 | D10: 22000 | E10: 22000 | F10: 22000 | G10: 22000 | H10: 22000 | I10: 22000 | J10: 22000 | K10: 22000 | L10: 22000 | M10: 22000 | N10: 22000 | O10: 22000 | P10: 22000 | Q10: 22000 | R10: 22000 | S10: 22000 | T10: 22000 | U10: 22000 | V10: 22000 | W10: 22000 | X10: 22000 | Y10: 22000 | Z10: 22000 | AA10: 22000 | AB10: 22000 | AC10: 22000 | AD10: 22000 | AE10: 22000 | AF10: 22000 | AG10: 22000 | AH10: 22000 | AI10: 22000 | AJ10: 22000
A11: Susan's Social Security | C11: 21600 | D11: 21600 | E11: 21600 | F11: 21600 | G11: 21600 | H11: 21600 | I11: 21600 | J11: 21600 | K11: 21600 | L11: 21600 | M11: 21600 | N11: 21600 | O11: 21600 | P11: 21600 | Q11: 21600 | R11: 21600 | S11: 21600 | T11: 21600 | U11: 21600 | V11: 21600 | W11: 21600 | X11: 21600 | Y11: 21600 | Z11: 21600 | AA11: 21600 | AB11: 21600 | AC11: 21600 | AD11: 21600 | AE11: 21600 | AF11: 21600 | AG11: 21600 | AH11: 21600 | AI11: 21600 | AJ11: 21600
A12: Bob's Social Security | C12: 0 | D12: 0 | E12: 0 | F12: 0 | G12: 0 | H12: 0 | I12: 0 | J12: 0 | P12: =5086*12 -> 61032 | Q12: =P12*1.02 -> 62252.64 | R12: =Q12*1.02 -> 63497.693 | S12: =R12*1.02 -> 64767.647 | T12: =S12*1.02 -> 66063 | U12: =T12*1.02 -> 67384.26 | V12: =U12*1.02 -> 68731.945 | W12: =V12*1.02 -> 70106.584 | X12: =W12*1.02 -> 71508.715 | ... AJ12: =AI12*1.02 -> 90690.341
A13: Susan's IRA | K13: =J31/VLOOKUP(K6,RMD!$B$4:$C$34,2,TRUE) -> 32520.325 | L13: =K31/VLOOKUP(L6,RMD!$B$4:$C$34,2,TRUE) -> 34408.425 | M13: =L31/VLOOKUP(M6,RMD!$B$4:$C$34,2,TRUE) -> 36244.543 | N13: =M31/VLOOKUP(N6,RMD!$B$4:$C$34,2,TRUE) -> 38343.431 | O13: =N31/VLOOKUP(O6,RMD!$B$4:$C$34,2,TRUE) -> 40560.445 | P13: =O31/VLOOKUP(P6,RMD!$B$4:$C$34,2,TRUE) -> 42901.706 | Q13: =P31/VLOOKUP(Q6,RMD!$B$4:$C$34,2,TRUE) -> 45139.672 | R13: =Q31/VLOOKUP(R6,RMD!$B$4:$C$34,2,TRUE) -> 47735.813 | ... AJ13: =AI31/VLOOKUP(AJ6,RMD!$B$4:$C$34,2,TRUE) -> 78511.033
A14: eTrade IRA | S14: =R34/VLOOKUP(S4,RMD!$B$4:$C$34,2,TRUE) -> 95248.18 | T14: =S34/VLOOKUP(T4,RMD!$B$4:$C$34,2,TRUE) -> 101187.18 | U14: =T34/VLOOKUP(U4,RMD!$B$4:$C$34,2,TRUE) -> 107069.2 | V14: =U34/VLOOKUP(V4,RMD!$B$4:$C$34,2,TRUE) -> 113285.54 | W14: =V34/VLOOKUP(W4,RMD!$B$4:$C$34,2,TRUE) -> 119330.74 | X14: =W34/VLOOKUP(X4,RMD!$B$4:$C$34,2,TRUE) -> 126241.07 | Y14: =X34/VLOOKUP(Y4,RMD!$B$4:$C$34,2,TRUE) -> 133540.32 | Z14: =Y34/VLOOKUP(Z4,RMD!$B$4:$C$34,2,TRUE) -> 141248.63 | ... AJ14: =AI34/VLOOKUP(AJ4,RMD!$B$4:$C$34,2,TRUE) -> 229287.5
A15: Bob's IRA | L15: 0 | M15: 0 | N15: 0 | O15: 0 | P15: 0 | Q15: 0 | R15: 0 | S15: =R32/VLOOKUP(S4,RMD!$B$4:$C$34,2,TRUE) -> 61648.841 | T15: =S32/VLOOKUP(T4,RMD!$B$4:$C$34,2,TRUE) -> 65492.827 | U15: =T32/VLOOKUP(U4,RMD!$B$4:$C$34,2,TRUE) -> 69299.931 | V15: =U32/VLOOKUP(V4,RMD!$B$4:$C$34,2,TRUE) -> 73323.42 | W15: =V32/VLOOKUP(W4,RMD!$B$4:$C$34,2,TRUE) -> 77236.137 | X15: =W32/VLOOKUP(X4,RMD!$B$4:$C$34,2,TRUE) -> 81708.812 | Y15: =X32/VLOOKUP(Y4,RMD!$B$4:$C$34,2,TRUE) -> 86433.207 | Z15: =Y32/VLOOKUP(Z4,RMD!$B$4:$C$34,2,TRUE) -> 91422.372 | ... AJ15: =AI32/VLOOKUP(AJ4,RMD!$B$4:$C$34,2,TRUE) -> 148405.02
A16: Bob's Roth | K16: 0 | L16: 0 | M16: 0 | N16: 0 | O16: 0 | P16: 0 | Q16: 0 | R16: 0 | S16: 0 | T16: 0 | U16: 0 | V16: 0 | W16: 0 | X16: 0 | Y16: 0 | Z16: 0 | AA16: 0 | AB16: 0 | AC16: 0 | AD16: 0 | AE16: 0 | AF16: 0 | AG16: 0 | AH16: 0 | AI16: 0 | AJ16: 0
A17: Wells Fargo Brokerage Account | K17: =IF(K24-(K21-K22)>0,K24-(K21-K22),0) -> 140803.23 | L17: =IF(L24-(L21-L22)>0,L24-(L21-L22),0) -> 149193.79 | M17: =IF(M24-(M21-M22)>0,M24-(M21-M22),0) -> 157914.29 | N17: =IF(N24-(N21-N22)>0,N24-(N21-N22),0) -> 166746.86 | O17: =IF(O24-(O21-O22)>0,O24-(O21-O22),0) -> 175804.7 | P17: =IF(P24-(P21-P22)>0,P24-(P21-P22),0) -> 141149.67 | Q17: =IF(Q24-(Q21-Q22)>0,Q24-(Q21-Q22),0) -> 149962.39 | R17: =IF(R24-(R21-R22)>0,R24-(R21-R22),0) -> 158841.11 | ... AJ17: =IF(AJ24-(AJ21-AJ22)>0,AJ24-(AJ21-AJ22),0) -> 0
Z18: =IF(Z24-(Z21-Z22)>0,Z24-(Z21-Z22),0) -> 15946.621 | AA18: =IF(AA24-(AA21-AA22)>0,AA24-(AA21-AA22),0) -> 5876.9916 | AB18: =IF(AB24-(AB21-AB22)>0,AB24-(AB21-AB22),0) -> 0
A19: Total Income Sources | C19: =SUM(C9:C17) -> 178286 | D19: =SUM(D9:D17) -> 178286 | E19: =SUM(E9:E17) -> 178286 | F19: =SUM(F9:F17) -> 178286 | G19: =SUM(G9:G17) -> 178286 | H19: =SUM(H9:H17) -> 178286 | I19: =SUM(I9:I17) -> 178286 | J19: =SUM(J9:J17) -> 178286 | ... AJ19: =SUM(AJ9:AJ17) -> 725179.89 | AL19: =SUM(C19:AK19) -> 15479292
A20: Non Taxable Income | C20: =C16 -> 0 | D20: =D16 -> 0 | E20: =E16 -> 0 | F20: =F16 -> 0 | G20: =G16 -> 0 | H20: =H16 -> 0 | I20: =I16 -> 0 | J20: =J16 -> 0 | K20: =K17+K16 -> 140803.23 | L20: =L17+L16 -> 149193.79 | M20: =M17+M16 -> 157914.29 | N20: =N17+N16 -> 166746.86 | O20: =O17+O16 -> 175804.7 | P20: =P17+P16 -> 141149.67 | Q20: =Q17+Q16 -> 149962.39 | R20: =R17+R16 -> 158841.11 | ... AJ20: =AJ17+AJ16 -> 0 | AL20: =SUM(C20:AK20) -> 1609662.3
A21: Taxable Income | C21: =SUM(C9:C15) -> 178286 | D21: =SUM(D9:D17) -> 178286 | E21: =SUM(E9:E17) -> 178286 | F21: =SUM(F9:F17) -> 178286 | G21: =SUM(G9:G17) -> 178286 | H21: =SUM(H9:H17) -> 178286 | I21: =SUM(I9:I17) -> 178286 | J21: =SUM(J9:J14) -> 178286 | K21: =SUM(K9:K14) -> 210806.33 | L21: =SUM(L9:L14) -> 212694.43 | M21: =SUM(M9:M14) -> 214530.54 | N21: =SUM(N9:N14) -> 216629.43 | O21: =SUM(O9:O14) -> 218846.44 | P21: =SUM(P9:P14) -> 282219.71 | Q21: =SUM(Q9:Q14) -> 285678.31 | R21: =SUM(R9:R14) -> 289519.51 | S21: =SUM(S9:S15) -> 450140.69 | T21: =SUM(T9:T15) -> 464093.01 | U21: =SUM(U9:U15) -> 477783.13 | V21: =SUM(V9:V15) -> 492157.83 | W21: =SUM(W9:W15) -> 506384.41 | X21: =SUM(X9:X15) -> 521698.28 | Y21: =SUM(Y9:Y15) -> 538235.76 | Z21: =SUM(Z9:Z15) -> 554996.58 | ... AJ21: =SUM(AJ9:AJ15) -> 725179.89 | AL21: =SUM(C21:AK21) -> 13869630
A22: Taxes Due | C22: =C40+C43 -> 26077.43 | D22: =D40+D43 -> 26077.43 | E22: =E40+E43 -> 26077.43 | F22: =F40+F43 -> 26077.43 | G22: =G40+G43 -> 26077.43 | H22: =H40+H43 -> 26743.86 | I22: =I40+I43 -> 26743.86 | J22: =J40+J43 -> 17555.36 | ... AJ22: =AJ40+AJ43 -> 202881.91
A23: Annual After Tax Income | H23: =H21-H22 -> 151542.14 | I23: =I21-I22 -> 151542.14 | J23: =J21-J22 -> 160730.64 | K23: =K21-K22 -> 184196.77 | L23: =L21-L22 -> 185556.21 | M23: =M21-M22 -> 186878.21 | N23: =N21-N22 -> 188389.41 | O23: =O21-O22 -> 189985.66 | ... AJ23: =AJ21-AJ22 -> 522297.99
A24: Total Net Income Target | C24: =C21-C22+C20 -> 152208.57 | D24: =D21-D22+D20 -> 152208.57 | E24: =E21-E22+E20 -> 152208.57 | F24: =F21-F22+F20 -> 152208.57 | G24: =G21-G22+G20 -> 152208.57 | H24: =H21-H22+H20 -> 151542.14 | I24: =I21-I22+I20 -> 151542.14 | J24: =J21-J22+J20 -> 160730.64 | K24: =Q7 -> 325000 | L24: =K24*$M7 -> 334750 | M24: =L24*$M7 -> 344792.5 | N24: =M24*$M7 -> 355136.28 | O24: =N24*$M7 -> 365790.36 | P24: =O24*$M7 -> 376764.07 | Q24: =P24*$M7 -> 388067 | R24: =Q24*$M7 -> 399709.01 | S24: =R24*$M7 -> 411700.28 | ... U24: =T24*$M7 -> 436772.82 | V24: =U24 -> 436772.82 | W24: =V24 -> 436772.82 | X24: =W24 -> 436772.82 | Y24: =X24 -> 436772.82 | Z24: =Y24 -> 436772.82 | AA24: =Z24 -> 436772.82 | AB24: =AA24 -> 436772.82 | AC24: =AB24 -> 436772.82 | ... AJ24: =AI24 -> 436772.82 | AL24: =SUM(C24:AK24) -> 11938984
A25: Total Net Income | K25: =K20+K21-K22 -> 325000 | L25: =L20+L21-L22 -> 334750 | M25: =M20+M21-M22 -> 344792.5 | N25: =N20+N21-N22 -> 355136.28 | O25: =O20+O21-O22 -> 365790.36 | P25: =P20+P21-P22 -> 376764.07 | Q25: =Q20+Q21-Q22 -> 388067 | R25: =R20+R21-R22 -> 399709.01 | ... U25: =U20+U21-U22 -> 436772.82 | V25: =U25 -> 436772.82 | W25: =V25 -> 436772.82 | X25: =W25 -> 436772.82 | Y25: =X25 -> 436772.82 | Z25: =Y25 -> 436772.82 | AA25: =Z25 -> 436772.82 | AB25: =AA25 -> 436772.82 | AC25: =AB25 -> 436772.82 | ... AJ25: =AI25 -> 436772.82
A26: Monthly after Tax Cash | C26: =C24/12 -> 12684.048 | D26: =D24/12 -> 12684.048 | E26: =E24/12 -> 12684.048 | F26: =F24/12 -> 12684.048 | G26: =G24/12 -> 12684.048 | H26: =H24/12 -> 12628.512 | I26: =I24/12 -> 12628.512 | J26: =J24/12 -> 13394.22 | ... AJ26: =AJ24/12 -> 36397.735 | AL26: =SUM(C26:AK26) -> 994915.31
A29: Account Balances
A30: Bob's Roth | C30: =370632*1.03-C16 -> 381750.96 | D30: =C30*$J$7-D16 -> 404656.02 | E30: =D30*$J$7-E16 -> 428935.38 | F30: =E30*$J$7-F16 -> 454671.5 | G30: =F30*$J$7-G16 -> 481951.79 | H30: 300000 | I30: =H30*$J$7-I16 -> 318000 | J30: =Sheet1!E5 -> 300000 | K30: =J30*$J$7-K16 -> 318000 | L30: =K30*$J$7-L16 -> 337080 | M30: =L30*$J$7-M16 -> 357304.8 | N30: =M30*$J$7-N16 -> 378743.09 | O30: =N30*$J$7-O16 -> 401467.67 | P30: =O30*$J$7-P16 -> 425555.73 | Q30: =P30*$J$7-Q16 -> 451089.08 | R30: =Q30*$J$7-R16 -> 478154.42 | ... AJ30: =AI30*$J$7-AJ16 -> 1364814.9
A31: Susan's IRA | C31: =566294*1.03-46500 -> 536782.82 | D31: =C31*$J$7-D13 -> 568989.79 | E31: =D31*$J$7-E13 -> 603129.18 | F31: =E31*$J$7-F13 -> 639316.93 | G31: =F31*$J$7-G13 -> 677675.94 | H31: 695000 | I31: =H31*$J$7-I13 -> 736700 | J31: =Sheet1!E6 -> 800000 | K31: =J31*$J$7-K13 -> 815479.67 | L31: =K31*$J$7-L13 -> 830000.03 | M31: =L31*$J$7-M13 -> 843555.49 | N31: =M31*$J$7-N13 -> 855825.39 | O31: =N31*$J$7-O13 -> 866614.47 | P31: =O31*$J$7-P13 -> 875709.63 | Q31: =P31*$J$7-Q13 -> 883112.53 | R31: =Q31*$J$7-R13 -> 888363.47 | ... AJ31: =AI31*$J$7-AJ13 -> 454107.81
A32: Bob's IRA | C32: =568057*1.03 -> 585098.71 | D32: =C32*$J$7-D15 -> 620204.63 | E32: =D32*$J$7-E15 -> 657416.91 | F32: =E32*$J$7-F15 -> 696861.93 | G32: =F32*$J$7-G15 -> 738673.64 | H32: 842000 | I32: =H32*$J$7-I15 -> 892520 | J32: =Sheet1!E4 -> 1025000 | K32: =J32*$J$7-K15 -> 1086500 | L32: =K32*$J$7-L15 -> 1151690 | M32: =L32*$J$7-M15 -> 1220791.4 | N32: =M32*$J$7-N15 -> 1294038.9 | O32: =N32*$J$7-O15 -> 1371681.2 | P32: =O32*$J$7-P15 -> 1453982.1 | Q32: =P32*$J$7-Q15 -> 1541221 | R32: =Q32*$J$7-R15 -> 1633694.3 | ... AJ32: =AI32*$J$7-AJ15 -> 1770768.7
A33: Wells Fargo Brokerage Account | C33: 451786 | D33: =C33*$J$7-D17 -> 478893.16 | E33: =D33*$J$7-E17 -> 507626.75 | F33: =E33*$J$7-F17 -> 538084.35 | G33: =F33*$J$7-G17 -> 570369.42 | H33: 650000 | I33: =H33*$J$7-I17 -> 689000 | J33: =Sheet1!E12 -> 2000000 | K33: =J33*$J$7-K17 -> 1979196.8 | L33: =K33*$J$7-L17 -> 1948754.8 | M33: =L33*$J$7-M17 -> 1907765.8 | N33: =M33*$J$7-N17 -> 1855484.9 | O33: =N33*$J$7-O17 -> 1791009.3 | P33: =O33*$J$7-P17 -> 1757320.1 | Q33: =P33*$J$7-Q17 -> 1712797 | R33: =Q33*$J$7-R17 -> 1656723.7 | ... AJ33: =AI33*$J$7-AJ17 -> 3878464.5
A34: eTrade IRA | H34: 908000 | I34: =H34*$J$7-I14 -> 962480 | J34: =Sheet1!E9 -> 1583637 | K34: =J34*$J$7-K14 -> 1678655.2 | L34: =K34*$J$7-L14 -> 1779374.5 | M34: =L34*$J$7-M14 -> 1886137 | N34: =M34*$J$7-N14 -> 1999305.2 | O34: =N34*$J$7-O14 -> 2119263.5 | P34: =O34*$J$7-P14 -> 2246419.4 | Q34: =P34*$J$7-Q14 -> 2381204.5 | R34: =Q34*$J$7-R14 -> 2524076.8 | ... AJ34: =AI34*$J$7-AJ14 -> 2735858.4
A35: Net Value | C35: =SUM(C30:C34) -> 1955418.5 | D35: =SUM(D30:D34) -> 2072743.6 | E35: =SUM(E30:E34) -> 2197108.2 | F35: =SUM(F30:F34) -> 2328934.7 | G35: =SUM(G30:G34) -> 2468670.8 | H35: =SUM(H30:H34) -> 3395000 | I35: =SUM(I30:I34) -> 3598700 | J35: =SUM(J30:J34) -> 5708637 | ... AJ35: =SUM(AJ30:AJ34) -> 10204014
A37: Gross Taxabale Income | C37: =C21 -> 178286 | D37: =D21 -> 178286 | E37: =E21 -> 178286 | F37: =F21 -> 178286 | G37: =G21 -> 178286 | H37: =H21 -> 178286 | I37: =I21 -> 178286 | J37: =J21 -> 178286 | ... AJ37: =AJ21 -> 725179.89
A38: Itemized Deductions | C38: 45000 | D38: =C38 -> 45000 | E38: =D38 -> 45000 | F38: =E38 -> 45000 | G38: =F38 -> 45000 | H38: =G38 -> 45000 | I38: =H38 -> 45000 | J38: 78000 | K38: 78000 | L38: 78000 | M38: 78000 | N38: 78000 | O38: 78000 | P38: 78000 | Q38: 78000 | R38: 78000 | S38: 78000 | T38: 78000 | U38: 78000 | V38: 78000 | W38: 78000 | X38: 78000 | Y38: 78000 | Z38: 78000 | AA38: 78000 | AB38: 78000 | AC38: 78000 | AD38: 78000 | AE38: 78000 | AF38: 78000 | AG38: 78000 | AH38: 78000 | AI38: 78000 | AJ38: 78000
A39: Net Taxable Income | C39: =C37-C38 -> 133286 | D39: =D37-D38 -> 133286 | E39: =E37-E38 -> 133286 | F39: =F37-F38 -> 133286 | G39: =G37-G38 -> 133286 | H39: =H37-H38 -> 133286 | I39: =I37-I38 -> 133286 | J39: =J37-J38 -> 100286 | ... AJ39: =AJ37-AJ38 -> 647179.89
A40: Federal Income Tax | C40: =VLOOKUP(C39,'Tax Table'!$B$5:$E$11,4,TRUE)+(C39-VLOOKUP(C39,'Tax Table'!$B$5:$E$11,1,TRUE))*VLOOKUP(C39,'Tax Table'!$B$5:$E$11,3,TRUE) -> 18746.7 | D40: =VLOOKUP(D39,'Tax Table'!$B$5:$E$11,4,TRUE)+(D39-VLOOKUP(D39,'Tax Table'!$B$5:$E$11,1,TRUE))*VLOOKUP(D39,'Tax Table'!$B$5:$E$11,3,TRUE) -> 18746.7 | E40: =VLOOKUP(E39,'Tax Table'!$B$5:$E$11,4,TRUE)+(E39-VLOOKUP(E39,'Tax Table'!$B$5:$E$11,1,TRUE))*VLOOKUP(E39,'Tax Table'!$B$5:$E$11,3,TRUE) -> 18746.7 | F40: =VLOOKUP(F39,'Tax Table'!$B$5:$E$11,4,TRUE)+(F39-VLOOKUP(F39,'Tax Table'!$B$5:$E$11,1,TRUE))*VLOOKUP(F39,'Tax Table'!$B$5:$E$11,3,TRUE) -> 18746.7 | G40: =VLOOKUP(G39,'Tax Table'!$B$5:$E$11,4,TRUE)+(G39-VLOOKUP(G39,'Tax Table'!$B$5:$E$11,1,TRUE))*VLOOKUP(G39,'Tax Table'!$B$5:$E$11,3,TRUE) -> 18746.7 | H40: =VLOOKUP(H39,'Tax Table'!$B$5:$E$11,4,TRUE)+(H39-VLOOKUP(H39,'Tax Table'!$B$5:$E$11,1,TRUE))*VLOOKUP(H39,'Tax Table'!$B$5:$E$11,3,TRUE) -> 18746.7 | I40: =VLOOKUP(I39,'Tax Table'!$B$5:$E$11,4,TRUE)+(I39-VLOOKUP(I39,'Tax Table'!$B$5:$E$11,1,TRUE))*VLOOKUP(I39,'Tax Table'!$B$5:$E$11,3,TRUE) -> 18746.7 | J40: =VLOOKUP(J39,'Tax Table'!$B$5:$E$11,4,TRUE)+(J39-VLOOKUP(J39,'Tax Table'!$B$5:$E$11,1,TRUE))*VLOOKUP(J39,'Tax Table'!$B$5:$E$11,3,TRUE) -> 11538.2 | ... AJ40: =VLOOKUP(AJ39,'Tax Table'!$B$5:$E$11,4,TRUE)+(AJ39-VLOOKUP(AJ39,'Tax Table'!$B$5:$E$11,1,TRUE))*VLOOKUP(AJ39,'Tax Table'!$B$5:$E$11,3,TRUE) -> 164051.11
A41: Marginal Rate | C41: =VLOOKUP(C39,'Tax Table'!$B$5:$E$11,3,TRUE) -> 0.22 | D41: =VLOOKUP(D39,'Tax Table'!$B$5:$E$11,3,TRUE) -> 0.22 | E41: =VLOOKUP(E39,'Tax Table'!$B$5:$E$11,3,TRUE) -> 0.22 | F41: =VLOOKUP(F39,'Tax Table'!$B$5:$E$11,3,TRUE) -> 0.22 | G41: =VLOOKUP(G39,'Tax Table'!$B$5:$E$11,3,TRUE) -> 0.22 | H41: =VLOOKUP(H39,'Tax Table'!$B$5:$E$11,3,TRUE) -> 0.22 | I41: =VLOOKUP(I39,'Tax Table'!$B$5:$E$11,3,TRUE) -> 0.22 | J41: =VLOOKUP(J39,'Tax Table'!$B$5:$E$11,3,TRUE) -> 0.12 | ... AJ41: =VLOOKUP(AJ39,'Tax Table'!$B$5:$E$11,3,TRUE) -> 0.35
A42: Effective Federal Rate | C42: =C40/C39 -> 0.14065018 | D42: =D40/D39 -> 0.14065018 | E42: =E40/E39 -> 0.14065018 | F42: =F40/F39 -> 0.14065018 | G42: =G40/G39 -> 0.14065018 | H42: =H40/H39 -> 0.14065018 | I42: =I40/I39 -> 0.14065018 | J42: =J40/J39 -> 0.11505295 | ... AJ42: =AJ40/AJ39 -> 0.25348611
A43: State Income Tax | C43: =0.055*C39 -> 7330.73 | D43: =0.055*D39 -> 7330.73 | E43: =0.055*E39 -> 7330.73 | F43: =0.055*F39 -> 7330.73 | G43: =0.055*G39 -> 7330.73 | H43: =0.06*H39 -> 7997.16 | I43: =0.06*I39 -> 7997.16 | J43: =0.06*J39 -> 6017.16 | K43: =0.06*K39 -> 7968.3795 | L43: =0.06*L39 -> 8081.6655 | M43: =0.06*M39 -> 8191.8326 | N43: =0.06*N39 -> 8317.7659 | O43: =0.06*O39 -> 8450.7867 | ... AJ43: =0.06*AJ39 -> 38830.793
A44: Effective Total Rate | C44: =(C43+C40)/C39 -> 0.19565018 | D44: =(D43+D40)/D39 -> 0.19565018 | E44: =(E43+E40)/E39 -> 0.19565018 | F44: =(F43+F40)/F39 -> 0.19565018 | G44: =(G43+G40)/G39 -> 0.19565018 | H44: =(H43+H40)/H39 -> 0.20065018 | I44: =(I43+I40)/I39 -> 0.20065018 | J44: =(J43+J40)/J39 -> 0.17505295 | ... AJ44: =(AJ43+AJ40)/AJ39 -> 0.31348611

Sheet Current Distribution with Roth
C3: 2019 | D3: 2020 | E3: 2021 | F3: 2022 | G3: 2023 | H3: 2024 | I3: 2025 | J3: 2026 | K3: 2027 | L3: 2028 | M3: 2029 | N3: 2030 | O3: 2031 | P3: 2032 | Q3: 2033 | R3: 2034 | S3: 2035 | T3: 2036 | U3: 2037 | V3: 2038 | W3: 2039 | X3: 2040 | Y3: 2041 | Z3: 2042 | AA3: 2043 | AB3: 2044 | AC3: 2045 | AD3: 2046 | AE3: 2047 | AF3: 2048 | AG3: 2049 | AH3: 2050 | AI3: 2051 | AJ3: 2052
A4: Age Mr. B | C4: 57 | D4: 58 | E4: 59 | F4: 60 | G4: 61 | H4: 62 | I4: 63 | J4: 64 | K4: 65 | L4: 66 | M4: 67 | N4: 68 | O4: 69 | P4: 70 | Q4: 71 | R4: 72 | S4: 73 | T4: 74 | U4: 75 | V4: 76 | W4: 77 | X4: 78 | Y4: 79 | Z4: 80 | AA4: 81 | AB4: 82 | AC4: 83 | AD4: 84 | AE4: 85 | AF4: 86 | AG4: 87 | AH4: 88 | AI4: 89 | AJ4: 90
L5: 1 | M5: 2 | N5: 3 | O5: 4 | P5: 5 | Q5: 6 | R5: 7
A6: Age Mrs. B | C6: 67 | D6: 68 | E6: 69 | F6: 70 | G6: 71 | H6: 72 | I6: 73 | J6: 74 | K6: 75 | L6: 76 | M6: 77 | N6: 78 | O6: 79 | P6: 80 | Q6: 81 | R6: 82 | S6: 83 | T6: 84 | U6: 85 | V6: 86 | W6: 87 | X6: 88 | Y6: 89 | Z6: 90 | AA6: 91 | AB6: 92 | AC6: 93 | AD6: 94 | AE6: 95 | AF6: 96 | AG6: 97 | AH6: 98 | AI6: 99 | AJ6: 100
I7: Rate of Return = | J7: 1.06 | L7: Inflation | M7: 1.03 | O7: Annual Afrer Tax Income | Q7: 325000 | S7: Interest | T7: 1.04
A8: Income Source
A9: Bob's Pension | C9: 134686 | D9: 134686 | E9: 134686 | F9: 134686 | G9: 134686 | H9: 134686 | I9: 134686 | J9: 134686 | K9: 134686 | L9: 134686 | M9: 134686 | N9: 134686 | O9: 134686 | P9: 134686 | Q9: 134686 | R9: 134686 | S9: 134686 | T9: 134686 | U9: 134686 | V9: 134686 | W9: 134686 | X9: 134686 | Y9: 134686 | Z9: 134686 | AA9: 134686 | AB9: 134686 | AC9: 134686 | AD9: 134686 | AE9: 134686 | AF9: 134686 | AG9: 134686 | AH9: 134686 | AI9: 134686 | AJ9: 134686
A10: Susan's Pension | C10: 22000 | D10: 22000 | E10: 22000 | F10: 22000 | G10: 22000 | H10: 22000 | I10: 22000 | J10: 22000 | K10: 22000 | L10: 22000 | M10: 22000 | N10: 22000 | O10: 22000 | P10: 22000 | Q10: 22000 | R10: 22000 | S10: 22000 | T10: 22000 | U10: 22000 | V10: 22000 | W10: 22000 | X10: 22000 | Y10: 22000 | Z10: 22000 | AA10: 22000 | AB10: 22000 | AC10: 22000 | AD10: 22000 | AE10: 22000 | AF10: 22000 | AG10: 22000 | AH10: 22000 | AI10: 22000 | AJ10: 22000
A11: Susan's Social Security | C11: 21600 | D11: 21600 | E11: 21600 | F11: 21600 | G11: 21600 | H11: 21600 | I11: 21600 | J11: 21600 | K11: 21600 | L11: 21600 | M11: 21600 | N11: 21600 | O11: 21600 | P11: 21600 | Q11: 21600 | R11: 21600 | S11: 21600 | T11: 21600 | U11: 21600 | V11: 21600 | W11: 21600 | X11: 21600 | Y11: 21600 | Z11: 21600 | AA11: 21600 | AB11: 21600 | AC11: 21600 | AD11: 21600 | AE11: 21600 | AF11: 21600 | AG11: 21600 | AH11: 21600 | AI11: 21600 | AJ11: 21600
A12: Bob's Social Security | C12: 0 | D12: 0 | E12: 0 | F12: 0 | G12: 0 | H12: 0 | I12: 0 | J12: 0 | P12: =5086*12 -> 61032 | Q12: =P12*1.02 -> 62252.64 | R12: =Q12*1.02 -> 63497.693 | S12: =R12*1.02 -> 64767.647 | T12: =S12*1.02 -> 66063 | U12: =T12*1.02 -> 67384.26 | V12: =U12*1.02 -> 68731.945 | W12: =V12*1.02 -> 70106.584 | X12: =W12*1.02 -> 71508.715 | ... AJ12: =AI12*1.02 -> 90690.341
A13: Susan's IRA | K13: =J36/VLOOKUP(K6,RMD!$B$4:$C$34,2,TRUE) -> 32520.325 | L13: =K36/VLOOKUP(L6,RMD!$B$4:$C$34,2,TRUE) -> 34408.425 | M13: =L36/VLOOKUP(M6,RMD!$B$4:$C$34,2,TRUE) -> 36244.543 | N13: =M36/VLOOKUP(N6,RMD!$B$4:$C$34,2,TRUE) -> 38343.431 | O13: =N36/VLOOKUP(O6,RMD!$B$4:$C$34,2,TRUE) -> 40560.445 | P13: =O36/VLOOKUP(P6,RMD!$B$4:$C$34,2,TRUE) -> 42901.706 | Q13: =P36/VLOOKUP(Q6,RMD!$B$4:$C$34,2,TRUE) -> 45139.672 | R13: =Q36/VLOOKUP(R6,RMD!$B$4:$C$34,2,TRUE) -> 47735.813 | ... AJ13: =AI36/VLOOKUP(AJ6,RMD!$B$4:$C$34,2,TRUE) -> 78511.033
A14: eTrade IRA | S14: =R39/VLOOKUP(S4,RMD!$B$4:$C$34,2,TRUE) -> 95248.18 | T14: =S39/VLOOKUP(T4,RMD!$B$4:$C$34,2,TRUE) -> 101187.18 | U14: =T39/VLOOKUP(U4,RMD!$B$4:$C$34,2,TRUE) -> 107069.2 | V14: =U39/VLOOKUP(V4,RMD!$B$4:$C$34,2,TRUE) -> 113285.54 | W14: =V39/VLOOKUP(W4,RMD!$B$4:$C$34,2,TRUE) -> 119330.74 | X14: =W39/VLOOKUP(X4,RMD!$B$4:$C$34,2,TRUE) -> 126241.07 | Y14: =X39/VLOOKUP(Y4,RMD!$B$4:$C$34,2,TRUE) -> 133540.32 | Z14: =Y39/VLOOKUP(Z4,RMD!$B$4:$C$34,2,TRUE) -> 141248.63 | ... AJ14: =AI39/VLOOKUP(AJ4,RMD!$B$4:$C$34,2,TRUE) -> 229287.5
A15: Bob's IRA | K15: =K24 -> 190743.67 | L15: =L24 -> 191273.75 | M15: =M24 -> 192363.74 | N15: =N24 -> 193753.31 | O15: =O24 -> 195633.61 | P15: =P24 -> 137022.95 | Q15: =Q24 -> 136611.96 | R15: 0 | S15: =R37/VLOOKUP(S4,RMD!$B$4:$C$34,2,TRUE) -> 1575.6701 | T15: =S37/VLOOKUP(T4,RMD!$B$4:$C$34,2,TRUE) -> 1673.9178 | U15: =T37/VLOOKUP(U4,RMD!$B$4:$C$34,2,TRUE) -> 1771.2227 | V15: =U37/VLOOKUP(V4,RMD!$B$4:$C$34,2,TRUE) -> 1874.0583 | W15: =V37/VLOOKUP(W4,RMD!$B$4:$C$34,2,TRUE) -> 1974.0626 | X15: =W37/VLOOKUP(X4,RMD!$B$4:$C$34,2,TRUE) -> 2088.3788 | Y15: =X37/VLOOKUP(Y4,RMD!$B$4:$C$34,2,TRUE) -> 2209.1286 | Z15: =Y37/VLOOKUP(Z4,RMD!$B$4:$C$34,2,TRUE) -> 2336.6457 | ... AJ15: =AI37/VLOOKUP(AJ4,RMD!$B$4:$C$34,2,TRUE) -> 3793.0535
A16: Bob's Roth | K16: 0 | L16: 0 | M16: 0 | N16: 0 | O16: 0 | P16: 0 | Q16: 0 | R16: 0 | S16: 0 | T16: 0 | U16: 0 | V16: 0 | W16: 0 | X16: 0 | Y16: 0 | Z16: 0 | AA16: 0 | AB16: 0 | AC16: 0 | AD16: 0 | AE16: 0 | AF16: 0 | AG16: 0 | AH16: 0 | AI16: 0 | AJ16: 0
A17: Wells Fargo Brokerage Account | K17: =K29-(K28-K24) -> 140454.43 | L17: =L29-(L28-L24) -> 150734.51 | M17: =M29-(M28-M24) -> 161867 | N17: =N29-(N28-N24) -> 173600.34 | O17: =O29-(O28-O24) -> 186134.74 | P17: =P29-(P28-P24) -> 138497.78 | Q17: =Q29-(Q28-Q24) -> 149389.71 | R17: =R29-(R28-R24) -> 119882.94 | S17: =IF((S29-S28)>0,(S29-S28),0) -> 63288.993 | T17: =IF((T29-T28)>0,(T29-T28),0) -> 69952.837 | U17: =IF((U29-U28)>0,(U29-U28),0) -> 76239.984 | V17: =IF((V29-V28)>0,(V29-V28),0) -> 69673.242 | W17: =IF((W29-W28)>0,(W29-W28),0) -> 62975.939 | X17: =IF((X29-X28)>0,(X29-X28),0) -> 56398.872 | Y17: =IF((Y29-Y28)>0,(Y29-Y28),0) -> 49239.369 | Z17: =IF((Z29-Z28)>0,(Z29-Z28),0) -> 41934.573 | ... AJ17: =IF((AJ29-AJ28)>0,(AJ29-AJ28),0) -> 0
Y18: =IF((Y29-Y28)>0,(Y29-Y28),0) -> 49239.369 | Z18: =IF((Z29-Z28)>0,(Z29-Z28),0) -> 41934.573 | AA18: =IF((AA29-AA28)>0,(AA29-AA28),0) -> 34633.971
A19: Total Income Sources | C19: =SUM(C9:C17) -> 178286 | D19: =SUM(D9:D17) -> 178286 | E19: =SUM(E9:E17) -> 178286 | F19: =SUM(F9:F17) -> 178286 | G19: =SUM(G9:G17) -> 178286 | H19: =SUM(H9:H17) -> 178286 | I19: =SUM(I9:I17) -> 178286 | J19: =SUM(J9:J17) -> 178286 | ... AJ19: =SUM(AJ9:AJ17) -> 580567.92 | AL19: =SUM(C19:AK19) -> 15127358
A20: Non Taxable Income | C20: =C16 -> 0 | D20: =D16 -> 0 | E20: =E16 -> 0 | F20: =F16 -> 0 | G20: =G16 -> 0 | H20: =H16 -> 0 | I20: =I16 -> 0 | J20: =J16 -> 0 | K20: =K17+K16 -> 140454.43 | L20: =L17+L16 -> 150734.51 | M20: =M17+M16 -> 161867 | N20: =N17+N16 -> 173600.34 | O20: =O17+O16 -> 186134.74 | P20: =P17+P16 -> 138497.78 | Q20: =Q17+Q16 -> 149389.71 | R20: =R17+R16 -> 119882.94 | ... AJ20: =AJ17+AJ16 -> 0 | AL20: =SUM(C20:AK20) -> 1800109.6
A21: Interest Income | K21: =($T$7-1)*J38 -> 80000 | L21: =($T$7-1)*K38 -> 77581.823 | M21: =($T$7-1)*L38 -> 74655.715 | N21: =($T$7-1)*M38 -> 71167.264 | O21: =($T$7-1)*N38 -> 67069.94 | P21: =($T$7-1)*O38 -> 62307.349 | Q21: =($T$7-1)*P38 -> 59259.731 | R21: =($T$7-1)*Q38 -> 55654.532 | ... AJ21: =($T$7-1)*AI38 -> 66172.807
A22: GrossTaxable Income before Roth | K22: =SUM(K9:K14)+K21 -> 290806.33 | L22: =SUM(L9:L14)+L21 -> 290276.25 | M22: =SUM(M9:M14)+M21 -> 289186.26 | N22: =SUM(N9:N14)+N21 -> 287796.69 | O22: =SUM(O9:O14)+O21 -> 285916.39 | P22: =SUM(P9:P14)+P21 -> 344527.05 | Q22: =SUM(Q9:Q14)+Q21 -> 344938.04 | R22: =SUM(R9:R14)+R21 -> 345174.04 | S22: =SUM(S9:S15)+S21 -> 443152.92 | T22: =SUM(T9:T14)+T21 -> 451277.44 | U22: =SUM(U9:U14)+U21 -> 460469.43 | V22: =SUM(V9:V14)+V21 -> 469850.49 | W22: =SUM(W9:W14)+W21 -> 479418.06 | X22: =SUM(X9:X14)+X21 -> 489751.02 | Y22: =SUM(Y9:Y14)+Y21 -> 501298.6 | Z22: =SUM(Z9:Z14)+Z21 -> 513080.53 | AA22: =SUM(AA9:AA14)+AA21 -> 524855.7 | ... AJ22: =SUM(AJ9:AJ14)+AJ21 -> 642947.68
A23: Base Taxable Income | C23: =SUM(C9:C15) -> 178286 | D23: =SUM(D9:D17) -> 178286 | E23: =SUM(E9:E17) -> 178286 | F23: =SUM(F9:F17) -> 178286 | G23: =SUM(G9:G17) -> 178286 | H23: =SUM(H9:H17) -> 178286 | I23: =SUM(I9:I17) -> 178286 | J23: =SUM(J9:J14) -> 178286 | K23: =SUM(K9:K14)+K21-K43 -> 212806.33 | L23: =SUM(L9:L14)+L21-L43 -> 212276.25 | M23: =SUM(M9:M14)+M21-M43 -> 211186.26 | N23: =SUM(N9:N14)+N21-N43 -> 209796.69 | O23: =SUM(O9:O14)+O21-O43 -> 207916.39 | P23: =SUM(P9:P14)+P21-P43 -> 266527.05 | Q23: =SUM(Q9:Q14)+Q21-Q43 -> 266938.04 | R23: =SUM(R9:R14)+R21-R43 -> 267174.04 | ... AA23: =SUM(AA9:AA14)+AA21-AA43 -> 446855.7 | AB23: =SUM(AB9:AB14) -> 487721.01 | AC23: =SUM(AC9:AC14) -> 499928.87 | AD23: =SUM(AD9:AD14) -> 512649.49 | AE23: =SUM(AE9:AE14) -> 524594.19 | AF23: =SUM(AF9:AF14) -> 535739.88 | AG23: =SUM(AG9:AG14) -> 548023.31 | AH23: =SUM(AH9:AH14) -> 557698.41 | AI23: =SUM(AI9:AI14) -> 568849.59 | AJ23: =SUM(AJ9:AJ14) -> 576774.87 | AL23: =SUM(C23:AK23) -> 11722467
A24: Taxable Roth Conversion | K24: ='Tax Table'!$C$8-'Current Distribution with Roth'!K23 -> 190743.67 | L24: ='Tax Table'!$C$8-'Current Distribution with Roth'!L23 -> 191273.75 | M24: ='Tax Table'!$C$8-'Current Distribution with Roth'!M23 -> 192363.74 | N24: ='Tax Table'!$C$8-'Current Distribution with Roth'!N23 -> 193753.31 | O24: ='Tax Table'!$C$8-'Current Distribution with Roth'!O23 -> 195633.61 | P24: ='Tax Table'!$C$8-'Current Distribution with Roth'!P23 -> 137022.95 | Q24: ='Tax Table'!$C$8-'Current Distribution with Roth'!Q23 -> 136611.96 | R24: 0 | S24: 0 | T24: 0 | U24: 0 | V24: 0 | W24: 0 | X24: 0 | Y24: 0 | Z24: 0 | AA24: 0 | AB24: 0 | AC24: 0 | AD24: 0 | AE24: 0 | AF24: 0 | AG24: 0 | AH24: 0 | AI24: 0 | AJ24: 0
A25: Gross Income with Roth | K25: =K22+K24 -> 481550 | L25: =L22+L24 -> 481550 | M25: =M22+M24 -> 481550 | N25: =N22+N24 -> 481550 | O25: =O22+O24 -> 481550 | P25: =P22+P24 -> 481550 | Q25: =Q22+Q24 -> 481550 | R25: =R22+R24 -> 345174.04 | ... AJ25: =AJ22+AJ24 -> 642947.68
A26: Taxable Income with Roth | C26: =SUM(C11:C17) -> 21600 | D26: =SUM(D11:D19) -> 199886 | E26: =SUM(E11:E19) -> 199886 | F26: =SUM(F11:F19) -> 199886 | G26: =SUM(G11:G19) -> 199886 | H26: =SUM(H11:H19) -> 199886 | I26: =SUM(I11:I19) -> 199886 | J26: =SUM(J11:J16) -> 21600 | K26: =K23+K24 -> 403550 | L26: =L23+L24 -> 403550 | M26: =M23+M24 -> 403550 | N26: =N23+N24 -> 403550 | O26: =O23+O24 -> 403550 | P26: =P23+P24 -> 403550 | Q26: =Q23+Q24 -> 403550 | R26: =R23+R24 -> 267174.04 | ... AJ26: =AJ23+AJ24 -> 576774.87 | AL26: =SUM(C26:AK26) -> 12776098
A27: Taxes Due | C27: =C45+C48 -> 26077.43 | D27: =D45+D48 -> 26077.43 | E27: =E45+E48 -> 26077.43 | F27: =F45+F48 -> 26077.43 | G27: =G45+G48 -> 26077.43 | H27: =H45+H48 -> 26743.86 | I27: =I45+I48 -> 26743.86 | J27: =J45+J48 -> 17555.36 | ... AJ27: =AJ45+AJ48 -> 169166.7
A28: Annual After Tax Income | H28: =H26-H27 -> 173142.14 | I28: =I26-I27 -> 173142.14 | J28: =J26-J27 -> 4044.64 | K28: =K25-K27 -> 375289.24 | L28: =L25-L27 -> 375289.24 | M28: =M25-M27 -> 375289.24 | N28: =N25-N27 -> 375289.24 | O28: =O25-O27 -> 375289.24 | P28: =P25-P27 -> 375289.24 | Q28: =Q25-Q27 -> 375289.24 | R28: =R25-R27 -> 279826.07 | ... AJ28: =AJ25-AJ27 -> 473780.98
A29: Total Net Income Target | C29: =C23-C27+C20 -> 152208.57 | D29: =D23-D27+D20 -> 152208.57 | E29: =E23-E27+E20 -> 152208.57 | F29: =F23-F27+F20 -> 152208.57 | G29: =G23-G27+G20 -> 152208.57 | H29: =H23-H27+H20 -> 151542.14 | I29: =I23-I27+I20 -> 151542.14 | J29: =J23-J27+J20 -> 160730.64 | K29: =Q7 -> 325000 | L29: =K29*$M7 -> 334750 | M29: =L29*$M7 -> 344792.5 | N29: =M29*$M7 -> 355136.28 | O29: =N29*$M7 -> 365790.36 | P29: =O29*$M7 -> 376764.07 | Q29: =P29*$M7 -> 388067 | R29: =Q29*$M7 -> 399709.01 | S29: =R29*$M7 -> 411700.28 | ... U29: =T29*$M7 -> 436772.82 | V29: =U29 -> 436772.82 | W29: =V29 -> 436772.82 | X29: =W29 -> 436772.82 | Y29: =X29 -> 436772.82 | Z29: =Y29 -> 436772.82 | AA29: =Z29 -> 436772.82 | AB29: =AA29 -> 436772.82 | AC29: =AB29 -> 436772.82 | ... AJ29: =AI29 -> 436772.82 | AL29: =SUM(C29:AK29) -> 11938984
A30: Total Net Income | K30: =K20+K28-K24 -> 325000 | L30: =L20+L28-L24 -> 334750 | M30: =M20+M28-M24 -> 344792.5 | N30: =N20+N28-N24 -> 355136.27 | O30: =O20+O28-O24 -> 365790.36 | P30: =P20+P28-P24 -> 376764.07 | Q30: =Q20+Q28-Q24 -> 388067 | R30: =R20+R28-R24 -> 399709.01 | S30: =S28+S17 -> 411700.28 | T30: =T28+T17 -> 424051.28 | U30: =U28+U17 -> 436772.82 | V30: =V28+V17 -> 436772.82 | W30: =W28+W17 -> 436772.82 | X30: =X28+X17 -> 436772.82 | Y30: =Y28+Y17 -> 436772.82 | Z30: =Z28+Z17 -> 436772.82 | ... AJ30: =AJ28+AJ17 -> 473780.98
A31: Monthly after Tax Cash | C31: =C29/12 -> 12684.048 | D31: =D29/12 -> 12684.048 | E31: =E29/12 -> 12684.048 | F31: =F29/12 -> 12684.048 | G31: =G29/12 -> 12684.048 | H31: =H29/12 -> 12628.512 | I31: =I29/12 -> 12628.512 | J31: =J29/12 -> 13394.22 | ... AJ31: =AJ29/12 -> 36397.735 | AL31: =SUM(C31:AK31) -> 994915.31
J33: Check | K33: =K20+K28-K24 -> 325000 | L33: =L20+L28-L24 -> 334750 | M33: =M20+M30-M24+M21 -> 388951.48 | N33: =N20+N30-N24+N21 -> 406150.57 | O33: =O20+O30-O24+O21 -> 423361.43 | P33: =P20+P30-P24+P21 -> 440546.26 | Q33: =Q20+Q30-Q24+Q21 -> 460104.48 | R33: =R20+R30-R24+R21 -> 575246.48 | S33: =S20+S30-S24+S21 -> 528074.66 | T33: =T20+T30-T24+T21 -> 546681.37 | U33: =U20+U30-U24+U21 -> 564999.04 | V33: =U33 -> 564999.04 | W33: =V33 -> 564999.04 | X33: =W33 -> 564999.04 | Y33: =X33 -> 564999.04 | Z33: =Y33 -> 564999.04 | AA33: =Z33 -> 564999.04 | AB33: =AA33 -> 564999.04 | AC33: =AB33 -> 564999.04 | ... AJ33: =AI33 -> 564999.04
A34: Account Balances
A35: Bob's Roth | C35: =370632*1.03-C16 -> 381750.96 | D35: =C35*$J$7-D16 -> 404656.02 | E35: =D35*$J$7-E16 -> 428935.38 | F35: =E35*$J$7-F16 -> 454671.5 | G35: =F35*$J$7-G16 -> 481951.79 | H35: 300000 | I35: =H35*$J$7-I16 -> 318000 | J35: =Sheet1!E5 -> 300000 | K35: =J35*$J$7-K16+K24 -> 508743.67 | L35: =K35*$J$7-L16+L24 -> 730542.05 | M35: =L35*$J$7-M16+M24 -> 966738.31 | N35: =M35*$J$7-N16+N24 -> 1218495.9 | O35: =N35*$J$7-O16+O24 -> 1487239.3 | P35: =O35*$J$7-P16+P24 -> 1713496.6 | Q35: =P35*$J$7-Q16+Q24 -> 1952918.3 | R35: =Q35*$J$7-R16+R24 -> 2070093.4 | S35: =R35*$J$7-S16 -> 2194299 | T35: =S35*$J$7-T16 -> 2325957 | U35: =T35*$J$7-U16 -> 2465514.4 | V35: =U35*$J$7-V16 -> 2613445.3 | W35: =V35*$J$7-W16 -> 2770252 | X35: =W35*$J$7-X16 -> 2936467.1 | Y35: =X35*$J$7-Y16 -> 3112655.1 | Z35: =Y35*$J$7-Z16 -> 3299414.4 | ... AJ35: =AI35*$J$7-AJ16 -> 5908748.8
A36: Susan's IRA | C36: =566294*1.03-46500 -> 536782.82 | D36: =C36*$J$7-D13 -> 568989.79 | E36: =D36*$J$7-E13 -> 603129.18 | F36: =E36*$J$7-F13 -> 639316.93 | G36: =F36*$J$7-G13 -> 677675.94 | H36: 695000 | I36: =H36*$J$7-I13 -> 736700 | J36: =Sheet1!E6 -> 800000 | K36: =J36*$J$7-K13 -> 815479.67 | L36: =K36*$J$7-L13 -> 830000.03 | M36: =L36*$J$7-M13 -> 843555.49 | N36: =M36*$J$7-N13 -> 855825.39 | O36: =N36*$J$7-O13 -> 866614.47 | P36: =O36*$J$7-P13 -> 875709.63 | Q36: =P36*$J$7-Q13 -> 883112.53 | R36: =Q36*$J$7-R13 -> 888363.47 | ... AJ36: =AI36*$J$7-AJ13 -> 454107.81
A37: Bob's IRA | C37: =568057*1.03 -> 585098.71 | D37: =C37*$J$7-D15 -> 620204.63 | E37: =D37*$J$7-E15 -> 657416.91 | F37: =E37*$J$7-F15 -> 696861.93 | G37: =F37*$J$7-G15 -> 738673.64 | H37: 842000 | I37: =H37*$J$7-I15 -> 892520 | J37: =Sheet1!E4 -> 1025000 | K37: =J37*$J$7-K15 -> 895756.33 | L37: =K37*$J$7-L15 -> 758227.95 | M37: =L37*$J$7-M15 -> 611357.89 | N37: =M37*$J$7-N15 -> 454286.06 | O37: =N37*$J$7-O15 -> 285909.6 | P37: =O37*$J$7-P15 -> 166041.24 | Q37: =P37*$J$7-Q15 -> 39391.752 | R37: =Q37*$J$7-R15 -> 41755.257 | ... AJ37: =AI37*$J$7-AJ15 -> 45258.715
A38: Wells Fargo Brokerage Account | C38: 451786 | D38: =C38*$J$7-D17 -> 478893.16 | E38: =D38*$J$7-E17 -> 507626.75 | F38: =E38*$J$7-F17 -> 538084.35 | G38: =F38*$J$7-G17 -> 570369.42 | H38: 650000 | I38: =H38*$J$7-I17 -> 689000 | J38: 2000000 | K38: =J38*$T$7-K17 -> 1939545.6 | L38: =K38*$T$7-L17 -> 1866392.9 | M38: =L38*$T$7-M17 -> 1779181.6 | N38: =M38*$T$7-N17 -> 1676748.5 | O38: =N38*$T$7-O17 -> 1557683.7 | P38: =O38*$T$7-P17 -> 1481493.3 | Q38: =P38*$T$7-Q17 -> 1391363.3 | R38: =Q38*$T$7-R17 -> 1327134.9 | ... AJ38: =AI38*$T$7-AJ17 -> 1720493
A39: eTrade IRA | H39: 908000 | I39: =H39*$J$7-I14 -> 962480 | J39: =Sheet1!E9 -> 1583637 | K39: =J39*$J$7-K14 -> 1678655.2 | L39: =K39*$J$7-L14 -> 1779374.5 | M39: =L39*$J$7-M14 -> 1886137 | N39: =M39*$J$7-N14 -> 1999305.2 | O39: =N39*$J$7-O14 -> 2119263.5 | P39: =O39*$J$7-P14 -> 2246419.4 | Q39: =P39*$J$7-Q14 -> 2381204.5 | R39: =Q39*$J$7-R14 -> 2524076.8 | ... AJ39: =AI39*$J$7-AJ14 -> 2735858.4
A40: Net Value | C40: =SUM(C35:C39) -> 1955418.5 | D40: =SUM(D35:D39) -> 2072743.6 | E40: =SUM(E35:E39) -> 2197108.2 | F40: =SUM(F35:F39) -> 2328934.7 | G40: =SUM(G35:G39) -> 2468670.8 | H40: =SUM(H35:H39) -> 3395000 | I40: =SUM(I35:I39) -> 3598700 | J40: =SUM(J35:J39) -> 5708637 | ... AJ40: =SUM(AJ35:AJ39) -> 10864467
A42: Gross Taxabale Income | C42: =C23 -> 178286 | D42: =D23 -> 178286 | E42: =E23 -> 178286 | F42: =F23 -> 178286 | G42: =G23 -> 178286 | H42: =H23 -> 178286 | I42: =I23 -> 178286 | J42: =J23 -> 178286 | K42: =K25 -> 481550 | L42: =L25 -> 481550 | M42: =M25 -> 481550 | N42: =N25 -> 481550 | O42: =O25 -> 481550 | P42: =P25 -> 481550 | Q42: =Q25 -> 481550 | R42: =R25 -> 345174.04 | ... AJ42: =AJ25 -> 642947.68
A43: Itemized Deductions | C43: 45000 | D43: =C43 -> 45000 | E43: =D43 -> 45000 | F43: =E43 -> 45000 | G43: =F43 -> 45000 | H43: =G43 -> 45000 | I43: =H43 -> 45000 | J43: 78000 | K43: 78000 | L43: 78000 | M43: 78000 | N43: 78000 | O43: 78000 | P43: 78000 | Q43: 78000 | R43: 78000 | S43: 78000 | T43: 78000 | U43: 78000 | V43: 78000 | W43: 78000 | X43: 78000 | Y43: 78000 | Z43: 78000 | AA43: 78000 | AB43: 78000 | AC43: 78000 | AD43: 78000 | AE43: 78000 | AF43: 78000 | AG43: 78000 | AH43: 78000 | AI43: 78000 | AJ43: 78000
A44: Net Taxable Income | C44: =C42-C43 -> 133286 | D44: =D42-D43 -> 133286 | E44: =E42-E43 -> 133286 | F44: =F42-F43 -> 133286 | G44: =G42-G43 -> 133286 | H44: =H42-H43 -> 133286 | I44: =I42-I43 -> 133286 | J44: =J42-J43 -> 100286 | ... AJ44: =AJ42-AJ43 -> 564947.68
...

Sheet Aggressive Model with Roth
C3: 2019 | D3: 2020 | E3: 2021 | F3: 2022 | G3: 2023 | H3: 2024 | I3: 2025 | J3: 2026 | K3: 2027 | L3: 2028 | M3: 2029 | N3: 2030 | O3: 2031 | P3: 2032 | Q3: 2033 | R3: 2034 | S3: 2035 | T3: 2036 | U3: 2037 | V3: 2038 | W3: 2039 | X3: 2040 | Y3: 2041 | Z3: 2042 | AA3: 2043 | AB3: 2044 | AC3: 2045 | AD3: 2046 | AE3: 2047 | AF3: 2048 | AG3: 2049 | AH3: 2050 | AI3: 2051 | AJ3: 2052
A4: Age Mr. B | C4: 57 | D4: 58 | E4: 59 | F4: 60 | G4: 61 | H4: 62 | I4: 63 | J4: 64 | K4: 65 | L4: 66 | M4: 67 | N4: 68 | O4: 69 | P4: 70 | Q4: 71 | R4: 72 | S4: 73 | T4: 74 | U4: 75 | V4: 76 | W4: 77 | X4: 78 | Y4: 79 | Z4: 80 | AA4: 81 | AB4: 82 | AC4: 83 | AD4: 84 | AE4: 85 | AF4: 86 | AG4: 87 | AH4: 88 | AI4: 89 | AJ4: 90
L5: 1 | M5: 2 | N5: 3 | O5: 4 | P5: 5 | Q5: 6 | R5: 7
A6: Age Mrs. B | C6: 67 | D6: 68 | E6: 69 | F6: 70 | G6: 71 | H6: 72 | I6: 73 | J6: 74 | K6: 75 | L6: 76 | M6: 77 | N6: 78 | O6: 79 | P6: 80 | Q6: 81 | R6: 82 | S6: 83 | T6: 84 | U6: 85 | V6: 86 | W6: 87 | X6: 88 | Y6: 89 | Z6: 90 | AA6: 91 | AB6: 92 | AC6: 93 | AD6: 94 | AE6: 95 | AF6: 96 | AG6: 97 | AH6: 98 | AI6: 99 | AJ6: 100
I7: Rate of Return = | J7: 1.06 | L7: Inflation | M7: 1.03 | O7: Annual Afrer Tax Income | Q7: 325000 | S7: Interest | T7: 1.04
A8: Income Source
A9: Bob's Pension | C9: 134686 | D9: 134686 | E9: 134686 | F9: 134686 | G9: 134686 | H9: 134686 | I9: 134686 | J9: 134686 | K9: 134686 | L9: 134686 | M9: 134686 | N9: 134686 | O9: 134686 | P9: 134686 | Q9: 134686 | R9: 134686 | S9: 134686 | T9: 134686 | U9: 134686 | V9: 134686 | W9: 134686 | X9: 134686 | Y9: 134686 | Z9: 134686 | AA9: 134686 | AB9: 134686 | AC9: 134686 | AD9: 134686 | AE9: 134686 | AF9: 134686 | AG9: 134686 | AH9: 134686 | AI9: 134686 | AJ9: 134686
A10: Susan's Pension | C10: 22000 | D10: 22000 | E10: 22000 | F10: 22000 | G10: 22000 | H10: 22000 | I10: 22000 | J10: 22000 | K10: 22000 | L10: 22000 | M10: 22000 | N10: 22000 | O10: 22000 | P10: 22000 | Q10: 22000 | R10: 22000 | S10: 22000 | T10: 22000 | U10: 22000 | V10: 22000 | W10: 22000 | X10: 22000 | Y10: 22000 | Z10: 22000 | AA10: 22000 | AB10: 22000 | AC10: 22000 | AD10: 22000 | AE10: 22000 | AF10: 22000 | AG10: 22000 | AH10: 22000 | AI10: 22000 | AJ10: 22000
A11: Susan's Social Security | C11: 21600 | D11: 21600 | E11: 21600 | F11: 21600 | G11: 21600 | H11: 21600 | I11: 21600 | J11: 21600 | K11: 21600 | L11: 21600 | M11: 21600 | N11: 21600 | O11: 21600 | P11: 21600 | Q11: 21600 | R11: 21600 | S11: 21600 | T11: 21600 | U11: 21600 | V11: 21600 | W11: 21600 | X11: 21600 | Y11: 21600 | Z11: 21600 | AA11: 21600 | AB11: 21600 | AC11: 21600 | AD11: 21600 | AE11: 21600 | AF11: 21600 | AG11: 21600 | AH11: 21600 | AI11: 21600 | AJ11: 21600
A12: Bob's Social Security | C12: 0 | D12: 0 | E12: 0 | F12: 0 | G12: 0 | H12: 0 | I12: 0 | J12: 0 | P12: =5086*12 -> 61032 | Q12: =P12*1.02 -> 62252.64 | R12: =Q12*1.02 -> 63497.693 | S12: =R12*1.02 -> 64767.647 | T12: =S12*1.02 -> 66063 | U12: =T12*1.02 -> 67384.26 | V12: =U12*1.02 -> 68731.945 | W12: =V12*1.02 -> 70106.584 | X12: =W12*1.02 -> 71508.715 | ... AJ12: =AI12*1.02 -> 90690.341
A13: Susan's IRA | K13: =J36/VLOOKUP(K6,RMD!$B$4:$C$34,2,TRUE) -> 32520.325 | L13: =K36/VLOOKUP(L6,RMD!$B$4:$C$34,2,TRUE) -> 35589.86 | M13: =L36/VLOOKUP(M6,RMD!$B$4:$C$34,2,TRUE) -> 38778.183 | N13: =M36/VLOOKUP(N6,RMD!$B$4:$C$34,2,TRUE) -> 42436.552 | O13: =N36/VLOOKUP(O6,RMD!$B$4:$C$34,2,TRUE) -> 46438.862 | P13: =O36/VLOOKUP(P6,RMD!$B$4:$C$34,2,TRUE) -> 50817.219 | Q13: =P36/VLOOKUP(Q6,RMD!$B$4:$C$34,2,TRUE) -> 55320.043 | R13: =Q36/VLOOKUP(R6,RMD!$B$4:$C$34,2,TRUE) -> 60532.088 | ... AJ13: =AI36/VLOOKUP(AJ6,RMD!$B$4:$C$34,2,TRUE) -> 188590.37
A14: eTrade IRA | S14: =R39/VLOOKUP(S4,RMD!$B$4:$C$34,2,TRUE) -> 123515.86 | T14: =S39/VLOOKUP(T4,RMD!$B$4:$C$34,2,TRUE) -> 135710.02 | U14: =T39/VLOOKUP(U4,RMD!$B$4:$C$34,2,TRUE) -> 148522.48 | V14: =U39/VLOOKUP(V4,RMD!$B$4:$C$34,2,TRUE) -> 162541.25 | W14: =V39/VLOOKUP(W4,RMD!$B$4:$C$34,2,TRUE) -> 177102.53 | X14: =W39/VLOOKUP(X4,RMD!$B$4:$C$34,2,TRUE) -> 193810.55 | Y14: =X39/VLOOKUP(Y4,RMD!$B$4:$C$34,2,TRUE) -> 212089.36 | Z14: =Y39/VLOOKUP(Z4,RMD!$B$4:$C$34,2,TRUE) -> 232085.61 | ... AJ14: =AI39/VLOOKUP(AJ4,RMD!$B$4:$C$34,2,TRUE) -> 531795.27
A15: Bob's IRA | K15: =K24 -> 190743.67 | L15: =L24 -> 190092.32 | M15: =M24 -> 189782.84 | N15: =N24 -> 189507.8 | O15: =O24 -> 189426.9 | P15: =P24 -> 128517.73 | Q15: =Q24 -> 125478.09 | R15: 0 | S15: =R37/VLOOKUP(S4,RMD!$B$4:$C$34,2,TRUE) -> 24246.398 | T15: =S37/VLOOKUP(T4,RMD!$B$4:$C$34,2,TRUE) -> 27522.039 | U15: =T37/VLOOKUP(U4,RMD!$B$4:$C$34,2,TRUE) -> 31118.923 | V15: =U37/VLOOKUP(V4,RMD!$B$4:$C$34,2,TRUE) -> 35186.705 | W15: =V37/VLOOKUP(W4,RMD!$B$4:$C$34,2,TRUE) -> 39613.469 | X15: =W37/VLOOKUP(X4,RMD!$B$4:$C$34,2,TRUE) -> 44793.831 | Y15: =X37/VLOOKUP(Y4,RMD!$B$4:$C$34,2,TRUE) -> 50653.118 | Z15: =Y37/VLOOKUP(Z4,RMD!$B$4:$C$34,2,TRUE) -> 57280.653 | ... AJ15: =AI37/VLOOKUP(AJ4,RMD!$B$4:$C$34,2,TRUE) -> 183153.56
A16: Bob's Roth | K16: 0 | L16: 0 | M16: 0 | N16: 0 | O16: 0 | P16: 0 | Q16: 0 | R16: 0 | S16: 0 | T16: 0 | U16: 0 | V16: 0 | W16: 0 | X16: 0 | Y16: 0 | Z16: 0 | AA16: 0 | AB16: 0 | AC16: 0 | AD16: 0 | AE16: 0 | AF16: 0 | AG16: 0 | AH16: 0 | AI16: 0 | AJ16: 0
A17: Wells Fargo Brokerage Account | K17: =K29-(K28-K24) -> 140454.43 | L17: =L29-(L28-L24) -> 149553.08 | M17: =M29-(M28-M24) -> 159286.1 | N17: =N29-(N28-N24) -> 169354.84 | O17: =O29-(O28-O24) -> 179928.02 | P17: =P29-(P28-P24) -> 129992.57 | Q17: =Q29-(Q28-Q24) -> 138255.85 | R17: =R29-(R28-R24) -> 109919.65 | S17: =IF((S29-S28)>0,(S29-S28),0) -> 17747.177 | T17: =IF((T29-T28)>0,(T29-T28),0) -> 32000.29 | U17: =IF((U29-U28)>0,(U29-U28),0) -> 31454.138 | V17: =IF((V29-V28)>0,(V29-V28),0) -> 17064.05 | W17: =IF((W29-W28)>0,(W29-W28),0) -> 1595.8359 | X17: =IF((X29-X28)>0,(X29-X28),0) -> 0 | Y17: =IF((Y29-Y28)>0,(Y29-Y28),0) -> 0 | Z17: =IF((Z29-Z28)>0,(Z29-Z28),0) -> 0 | ... AJ17: =IF((AJ29-AJ28)>0,(AJ29-AJ28),0) -> 0
Y18: =IF((Y29-Y28)>0,(Y29-Y28),0) -> 0 | Z18: =IF((Z29-Z28)>0,(Z29-Z28),0) -> 0 | AA18: =IF((AA29-AA28)>0,(AA29-AA28),0) -> 0
A19: Total Income Sources | C19: =SUM(C9:C17) -> 178286 | D19: =SUM(D9:D17) -> 178286 | E19: =SUM(E9:E17) -> 178286 | F19: =SUM(F9:F17) -> 178286 | G19: =SUM(G9:G17) -> 178286 | H19: =SUM(H9:H17) -> 178286 | I19: =SUM(I9:I17) -> 178286 | J19: =SUM(J9:J17) -> 178286 | ... AJ19: =SUM(AJ9:AJ17) -> 1172515.5 | AL19: =SUM(C19:AK19) -> 19479570
A20: Non Taxable Income | C20: =C16 -> 0 | D20: =D16 -> 0 | E20: =E16 -> 0 | F20: =F16 -> 0 | G20: =G16 -> 0 | H20: =H16 -> 0 | I20: =I16 -> 0 | J20: =J16 -> 0 | K20: =K17+K16 -> 140454.43 | L20: =L17+L16 -> 149553.08 | M20: =M17+M16 -> 159286.1 | N20: =N17+N16 -> 169354.84 | O20: =O17+O16 -> 179928.02 | P20: =P17+P16 -> 129992.57 | Q20: =Q17+Q16 -> 138255.85 | R20: =R17+R16 -> 109919.65 | ... AJ20: =AJ17+AJ16 -> 0 | AL20: =SUM(C20:AK20) -> 1276606
A21: Interest Income | K21: =(Sheet1!$C$21-1)*J38 -> 80000 | L21: =(Sheet1!$C$21-1)*K38 -> 77581.823 | M21: =(Sheet1!$C$21-1)*L38 -> 74702.972 | N21: =(Sheet1!$C$21-1)*M38 -> 71319.647 | O21: =(Sheet1!$C$21-1)*N38 -> 67398.24 | P21: =(Sheet1!$C$21-1)*O38 -> 62897.048 | Q21: =(Sheet1!$C$21-1)*P38 -> 60213.227 | R21: =(Sheet1!$C$21-1)*Q38 -> 57091.523 | ... AJ21: =(Sheet1!$C$21-1)*AI38 -> 100040.16
A22: GrossTaxable Income before Roth | K22: =SUM(K9:K14)+K21 -> 290806.33 | L22: =SUM(L9:L14)+L21 -> 291457.68 | M22: =SUM(M9:M14)+M21 -> 291767.16 | N22: =SUM(N9:N14)+N21 -> 292042.2 | O22: =SUM(O9:O14)+O21 -> 292123.1 | P22: =SUM(P9:P14)+P21 -> 353032.27 | Q22: =SUM(Q9:Q14)+Q21 -> 356071.91 | R22: =SUM(R9:R14)+R21 -> 359407.3 | S22: =SUM(S9:S15)+S21 -> 511652.87 | T22: =SUM(T9:T14)+T21 -> 508584.96 | U22: =SUM(U9:U14)+U21 -> 529984.46 | V22: =SUM(V9:V14)+V21 -> 553194.28 | W22: =SUM(W9:W14)+W21 -> 578143.01 | X22: =SUM(X9:X14)+X21 -> 605806.38 | Y22: =SUM(Y9:Y14)+Y21 -> 636529.3 | Z22: =SUM(Z9:Z14)+Z21 -> 668794.15 | AA22: =SUM(AA9:AA14)+AA21 -> 702247.81 | ... AJ22: =SUM(AJ9:AJ14)+AJ21 -> 1089402.1
A23: Base Taxable Income | C23: =SUM(C9:C15) -> 178286 | D23: =SUM(D9:D17) -> 178286 | E23: =SUM(E9:E17) -> 178286 | F23: =SUM(F9:F17) -> 178286 | G23: =SUM(G9:G17) -> 178286 | H23: =SUM(H9:H17) -> 178286 | I23: =SUM(I9:I17) -> 178286 | J23: =SUM(J9:J14) -> 178286 | K23: =SUM(K9:K14)+K21-K43 -> 212806.33 | L23: =SUM(L9:L14)+L21-L43 -> 213457.68 | M23: =SUM(M9:M14)+M21-M43 -> 213767.16 | N23: =SUM(N9:N14)+N21-N43 -> 214042.2 | O23: =SUM(O9:O14)+O21-O43 -> 214123.1 | P23: =SUM(P9:P14)+P21-P43 -> 275032.27 | Q23: =SUM(Q9:Q14)+Q21-Q43 -> 278071.91 | R23: =SUM(R9:R14)+R21-R43 -> 281407.3 | ... AA23: =SUM(AA9:AA14)+AA21-AA43 -> 624247.81 | AB23: =SUM(AB9:AB14) -> 666465.04 | AC23: =SUM(AC9:AC14) -> 701994.7 | AD23: =SUM(AD9:AD14) -> 740367.75 | AE23: =SUM(AE9:AE14) -> 779299.68 | AF23: =SUM(AF9:AF14) -> 818640.07 | AG23: =SUM(AG9:AG14) -> 862467.2 | AH23: =SUM(AH9:AH14) -> 902929.56 | AI23: =SUM(AI9:AI14) -> 948740.18 | AJ23: =SUM(AJ9:AJ14) -> 989361.97 | AL23: =SUM(C23:AK23) -> 15307953
A24: Taxable Roth Conversion | K24: ='Tax Table'!$C$8-'Aggressive Model with Roth'!K23 -> 190743.67 | L24: ='Tax Table'!$C$8-'Aggressive Model with Roth'!L23 -> 190092.32 | M24: ='Tax Table'!$C$8-'Aggressive Model with Roth'!M23 -> 189782.84 | N24: ='Tax Table'!$C$8-'Aggressive Model with Roth'!N23 -> 189507.8 | O24: ='Tax Table'!$C$8-'Aggressive Model with Roth'!O23 -> 189426.9 | P24: ='Tax Table'!$C$8-'Aggressive Model with Roth'!P23 -> 128517.73 | Q24: ='Tax Table'!$C$8-'Aggressive Model with Roth'!Q23 -> 125478.09 | R24: 0 | S24: 0 | T24: 0 | U24: 0 | V24: 0 | W24: 0 | X24: 0 | Y24: 0 | Z24: 0 | AA24: 0 | AB24: 0 | AC24: 0 | AD24: 0 | AE24: 0 | AF24: 0 | AG24: 0 | AH24: 0 | AI24: 0 | AJ24: 0
A25: Gross Income with Roth | K25: =K22+K24 -> 481550 | L25: =L22+L24 -> 481550 | M25: =M22+M24 -> 481550 | N25: =N22+N24 -> 481550 | O25: =O22+O24 -> 481550 | P25: =P22+P24 -> 481550 | Q25: =Q22+Q24 -> 481550 | R25: =R22+R24 -> 359407.3 | ... AJ25: =AJ22+AJ24 -> 1089402.1
A26: Taxable Income with Roth | C26: =SUM(C11:C17) -> 21600 | D26: =SUM(D11:D19) -> 199886 | E26: =SUM(E11:E19) -> 199886 | F26: =SUM(F11:F19) -> 199886 | G26: =SUM(G11:G19) -> 199886 | H26: =SUM(H11:H19) -> 199886 | I26: =SUM(I11:I19) -> 199886 | J26: =SUM(J11:J16) -> 21600 | K26: =K23+K24 -> 403550 | L26: =L23+L24 -> 403550 | M26: =M23+M24 -> 403550 | N26: =N23+N24 -> 403550 | O26: =O23+O24 -> 403550 | P26: =P23+P24 -> 403550 | Q26: =Q23+Q24 -> 403550 | R26: =R23+R24 -> 281407.3 | ... AJ26: =AJ23+AJ24 -> 989361.97 | AL26: =SUM(C26:AK26) -> 16327730
A27: Taxes Due | C27: =C45+C48 -> 26077.43 | D27: =D45+D48 -> 26077.43 | E27: =E45+E48 -> 26077.43 | F27: =F45+F48 -> 26077.43 | G27: =G45+G48 -> 26077.43 | H27: =H45+H48 -> 26743.86 | I27: =I45+I48 -> 26743.86 | J27: =J45+J48 -> 17555.36 | ... AJ27: =AJ45+AJ48 -> 357067.05
A28: Annual After Tax Income | H28: =H26-H27 -> 173142.14 | I28: =I26-I27 -> 173142.14 | J28: =J26-J27 -> 4044.64 | K28: =K25-K27 -> 375289.24 | L28: =L25-L27 -> 375289.24 | M28: =M25-M27 -> 375289.24 | N28: =N25-N27 -> 375289.24 | O28: =O25-O27 -> 375289.24 | P28: =P25-P27 -> 375289.24 | Q28: =Q25-Q27 -> 375289.24 | R28: =R25-R27 -> 289789.35 | ... AJ28: =AJ25-AJ27 -> 732335.09
A29: Total Net Income Target | C29: =C23-C27+C20 -> 152208.57 | D29: =D23-D27+D20 -> 152208.57 | E29: =E23-E27+E20 -> 152208.57 | F29: =F23-F27+F20 -> 152208.57 | G29: =G23-G27+G20 -> 152208.57 | H29: =H23-H27+H20 -> 151542.14 | I29: =I23-I27+I20 -> 151542.14 | J29: =J23-J27+J20 -> 160730.64 | K29: =Q7 -> 325000 | L29: =K29*$M7 -> 334750 | M29: =L29*$M7 -> 344792.5 | N29: =M29*$M7 -> 355136.28 | O29: =N29*$M7 -> 365790.36 | P29: =O29*$M7 -> 376764.07 | Q29: =P29*$M7 -> 388067 | R29: =Q29*$M7 -> 399709.01 | S29: =R29*$M7 -> 411700.28 | ... U29: =T29*$M7 -> 436772.82 | V29: =U29 -> 436772.82 | W29: =V29 -> 436772.82 | X29: =W29 -> 436772.82 | Y29: =X29 -> 436772.82 | Z29: =Y29 -> 436772.82 | AA29: =Z29 -> 436772.82 | AB29: =AA29 -> 436772.82 | AC29: =AB29 -> 436772.82 | ... AJ29: =AI29 -> 436772.82 | AL29: =SUM(C29:AK29) -> 11938984
A30: Total Net Income | K30: =K20+K28-K24 -> 325000 | L30: =L20+L28-L24 -> 334750 | M30: =M20+M28-M24 -> 344792.5 | N30: =N20+N28-N24 -> 355136.28 | O30: =O20+O28-O24 -> 365790.36 | P30: =P20+P28-P24 -> 376764.07 | Q30: =Q20+Q28-Q24 -> 388067 | R30: =R20+R28-R24 -> 399709.01 | S30: =S28+S17 -> 411700.28 | T30: =T28+T17 -> 424051.28 | U30: =U28+U17 -> 436772.82 | V30: =V28+V17 -> 436772.82 | W30: =W28+W17 -> 436772.82 | X30: =X28+X17 -> 451867.61 | Y30: =Y28+Y17 -> 469994.13 | Z30: =Z28+Z17 -> 489030.4 | ... AJ30: =AJ28+AJ17 -> 732335.09
A31: Monthly after Tax Cash | C31: =C29/12 -> 12684.048 | D31: =D29/12 -> 12684.048 | E31: =E29/12 -> 12684.048 | F31: =F29/12 -> 12684.048 | G31: =G29/12 -> 12684.048 | H31: =H29/12 -> 12628.512 | I31: =I29/12 -> 12628.512 | J31: =J29/12 -> 13394.22 | ... AJ31: =AJ29/12 -> 36397.735 | AL31: =SUM(C31:AK31) -> 994915.31
J33: Check | K33: =K20+K28-K24 -> 325000 | L33: =L20+L28-L24 -> 334750 | M33: =M20+M30-M24+M21 -> 388998.73 | N33: =N20+N30-N24+N21 -> 406302.96 | O33: =O20+O30-O24+O21 -> 423689.73 | P33: =P20+P30-P24+P21 -> 441135.96 | Q33: =Q20+Q30-Q24+Q21 -> 461057.98 | R33: =R20+R30-R24+R21 -> 566720.18 | S33: =S20+S30-S24+S21 -> 484425.85 | T33: =T20+T30-T24+T21 -> 512519.22 | U33: =U20+U30-U24+U21 -> 525673.3 | V33: =U33 -> 525673.3 | W33: =V33 -> 525673.3 | X33: =W33 -> 525673.3 | Y33: =X33 -> 525673.3 | Z33: =Y33 -> 525673.3 | AA33: =Z33 -> 525673.3 | AB33: =AA33 -> 525673.3 | AC33: =AB33 -> 525673.3 | ... AJ33: =AI33 -> 525673.3
A34: Account Balances
A35: Bob's Roth | C35: =370632*1.03-C16 -> 381750.96 | D35: =C35*$J$7-D16 -> 404656.02 | E35: =D35*$J$7-E16 -> 428935.38 | F35: =E35*$J$7-F16 -> 454671.5 | G35: =F35*$J$7-G16 -> 481951.79 | H35: 300000 | I35: =H35*$J$7-I16 -> 318000 | J35: =Sheet1!E5 -> 300000 | K35: =J35*Sheet1!$C$18-K16+K24 -> 541743.67 | L35: =K35*Sheet1!$C$18-L16+L24 -> 823932.42 | M35: =L35*Sheet1!$C$18-M16+M24 -> 1153783.8 | N35: =M35*Sheet1!$C$18-N16+N24 -> 1539434.8 | O35: =N35*Sheet1!$C$18-O16+O24 -> 1990565.6 | P35: =O35*Sheet1!$C$18-P16+P24 -> 2457479.5 | Q35: =P35*Sheet1!$C$18-Q16+Q24 -> 3000729.1 | R35: =Q35*Sheet1!$C$18-R16+R24 -> 3510853.1 | S35: =R35*Sheet1!$C$18-S16 -> 4107698.1 | T35: =S35*Sheet1!$C$18-T16 -> 4806006.8 | U35: =T35*Sheet1!$C$18-U16 -> 5623027.9 | V35: =U35*Sheet1!$C$18-V16 -> 6578942.7 | W35: =V35*Sheet1!$C$18-W16 -> 7697362.9 | X35: =W35*Sheet1!$C$18-X16 -> 9005914.7 | Y35: =X35*Sheet1!$C$18-Y16 -> 10536920 | Z35: =Y35*Sheet1!$C$18-Z16 -> 12328197 | ... AJ35: =AI35*Sheet1!$C$18-AJ16 -> 59259525
A36: Susan's IRA | C36: =566294*1.03-46500 -> 536782.82 | D36: =C36*$J$7-D13 -> 568989.79 | E36: =D36*$J$7-E13 -> 603129.18 | F36: =E36*$J$7-F13 -> 639316.93 | G36: =F36*$J$7-G13 -> 677675.94 | H36: 695000 | I36: =H36*$J$7-I13 -> 736700 | J36: =Sheet1!E6 -> 800000 | K36: =J36*Sheet1!$C$19-K13 -> 843479.67 | L36: =K36*Sheet1!$C$19-L13 -> 888020.38 | M36: =L36*Sheet1!$C$19-M13 -> 933604.14 | N36: =M36*Sheet1!$C$19-N13 -> 979859.98 | O36: =N36*Sheet1!$C$19-O13 -> 1026507.8 | P36: =O36*Sheet1!$C$19-P13 -> 1073208.8 | Q36: =P36*Sheet1!$C$19-Q13 -> 1119843.6 | R36: =Q36*Sheet1!$C$19-R13 -> 1165696.7 | ... AJ36: =AI36*Sheet1!$C$19-AJ13 -> 1133050.9
A37: Bob's IRA | C37: =568057*1.03 -> 585098.71 | D37: =C37*$J$7-D15 -> 620204.63 | E37: =D37*$J$7-E15 -> 657416.91 | F37: =E37*$J$7-F15 -> 696861.93 | G37: =F37*$J$7-G15 -> 738673.64 | H37: 842000 | I37: =H37*$J$7-I15 -> 892520 | J37: =Sheet1!E4 -> 1025000 | K37: =J37*Sheet1!$C$20-K15 -> 967506.33 | L37: =K37*Sheet1!$C$20-L15 -> 903189.83 | M37: =L37*Sheet1!$C$20-M15 -> 830821.66 | N37: =M37*Sheet1!$C$20-N15 -> 749320.68 | O37: =N37*Sheet1!$C$20-O15 -> 657305.47 | P37: =O37*Sheet1!$C$20-P15 -> 614237.44 | Q37: =P37*Sheet1!$C$20-Q15 -> 568610.22 | R37: =Q37*Sheet1!$C$20-R15 -> 642529.55 | ... AJ37: =AI37*Sheet1!$C$20-AJ15 -> 2341801.4
A38: Wells Fargo Brokerage Account | C38: 451786 | D38: =C38*$J$7-D17 -> 478893.16 | E38: =D38*$J$7-E17 -> 507626.75 | F38: =E38*$J$7-F17 -> 538084.35 | G38: =F38*$J$7-G17 -> 570369.42 | H38: 650000 | I38: =H38*$J$7-I17 -> 689000 | J38: 2000000 | K38: =J38*Sheet1!$C$21-K17 -> 1939545.6 | L38: =K38*Sheet1!$C$21-L17 -> 1867574.3 | M38: =L38*Sheet1!$C$21-M17 -> 1782991.2 | N38: =M38*Sheet1!$C$21-N17 -> 1684956 | O38: =N38*Sheet1!$C$21-O17 -> 1572426.2 | P38: =O38*Sheet1!$C$21-P17 -> 1505330.7 | Q38: =P38*Sheet1!$C$21-Q17 -> 1427288.1 | R38: =Q38*Sheet1!$C$21-R17 -> 1374459.9 | ... AJ38: =AI38*Sheet1!$C$21-AJ17 -> 2601044.2
A39: eTrade IRA | H39: 908000 | I39: =H39*$J$7-I14 -> 962480 | J39: =Sheet1!E9 -> 1583637 | K39: =J39*Sheet1!$C$22-K14 -> 1734082.5 | L39: =K39*Sheet1!$C$22-L14 -> 1898820.4 | M39: =L39*Sheet1!$C$22-M14 -> 2079208.3 | N39: =M39*Sheet1!$C$22-N14 -> 2276733.1 | O39: =N39*Sheet1!$C$22-O14 -> 2493022.7 | P39: =O39*Sheet1!$C$22-P14 -> 2729859.9 | Q39: =P39*Sheet1!$C$22-Q14 -> 2989196.6 | R39: =Q39*Sheet1!$C$22-R14 -> 3273170.2 | ... AJ39: =AI39*Sheet1!$C$22-AJ14 -> 6572457.7
A40: Net Value | C40: =SUM(C35:C39) -> 1955418.5 | D40: =SUM(D35:D39) -> 2072743.6 | E40: =SUM(E35:E39) -> 2197108.2 | F40: =SUM(F35:F39) -> 2328934.7 | G40: =SUM(G35:G39) -> 2468670.8 | H40: =SUM(H35:H39) -> 3395000 | I40: =SUM(I35:I39) -> 3598700 | J40: =SUM(J35:J39) -> 5708637 | ... AJ40: =SUM(AJ35:AJ39) -> 71907879
A42: Gross Taxabale Income | C42: =C23 -> 178286 | D42: =D23 -> 178286 | E42: =E23 -> 178286 | F42: =F23 -> 178286 | G42: =G23 -> 178286 | H42: =H23 -> 178286 | I42: =I23 -> 178286 | J42: =J23 -> 178286 | K42: =K25 -> 481550 | L42: =L25 -> 481550 | M42: =M25 -> 481550 | N42: =N25 -> 481550 | O42: =O25 -> 481550 | P42: =P25 -> 481550 | Q42: =Q25 -> 481550 | R42: =R25 -> 359407.3 | ... AJ42: =AJ25 -> 1089402.1
A43: Itemized Deductions | C43: 45000 | D43: =C43 -> 45000 | E43: =D43 -> 45000 | F43: =E43 -> 45000 | G43: =F43 -> 45000 | H43: =G43 -> 45000 | I43: =H43 -> 45000 | J43: 78000 | K43: 78000 | L43: 78000 | M43: 78000 | N43: 78000 | O43: 78000 | P43: 78000 | Q43: 78000 | R43: 78000 | S43: 78000 | T43: 78000 | U43: 78000 | V43: 78000 | W43: 78000 | X43: 78000 | Y43: 78000 | Z43: 78000 | AA43: 78000 | AB43: 78000 | AC43: 78000 | AD43: 78000 | AE43: 78000 | AF43: 78000 | AG43: 78000 | AH43: 78000 | AI43: 78000 | AJ43: 78000
A44: Net Taxable Income | C44: =C42-C43 -> 133286 | D44: =D42-D43 -> 133286 | E44: =E42-E43 -> 133286 | F44: =F42-F43 -> 133286 | G44: =G42-G43 -> 133286 | H44: =H42-H43 -> 133286 | I44: =I42-I43 -> 133286 | J44: =J42-J43 -> 100286 | ... AJ44: =AJ42-AJ43 -> 1011402.1
...

Sheet Compare
C3: 2025 | D3: 2026 | E3: 2027 | F3: 2028 | G3: 2029 | H3: 2030 | I3: 2031 | J3: 2032 | K3: 2033 | L3: 2034 | M3: 2035 | N3: 2036 | O3: 2037 | P3: 2038 | Q3: 2039 | R3: 2040 | S3: 2041 | T3: 2042 | U3: 2043 | V3: 2044 | W3: 2045 | X3: 2046 | Y3: 2047 | Z3: 2048 | AA3: 2049 | AB3: 2050 | AC3: 2051 | AD3: 2052
A4: Age Mr. B | C4: 63 | D4: 64 | E4: 65 | F4: 66 | G4: 67 | H4: 68 | I4: 69 | J4: 70 | K4: 71 | L4: 72 | M4: 73 | N4: 74 | O4: 75 | P4: 76 | Q4: 77 | R4: 78 | S4: 79 | T4: 80 | U4: 81 | V4: 82 | W4: 83 | X4: 84 | Y4: 85 | Z4: 86 | AA4: 87 | AB4: 88 | AC4: 89 | AD4: 90
A5: Age Mrs. B | C5: 73 | D5: 74 | E5: 75 | F5: 76 | G5: 77 | H5: 78 | I5: 79 | J5: 80 | K5: 81 | L5: 82 | M5: 83 | N5: 84 | O5: 85 | P5: 86 | Q5: 87 | R5: 88 | S5: 89 | T5: 90 | U5: 91 | V5: 92 | W5: 93 | X5: 94 | Y5: 95 | Z5: 96 | AA5: 97 | AB5: 98 | AC5: 99 | AD5: 100
A7: Income Source
A8: Bob's Pension | C8: ='Current Distribution with Roth'!H9-'Current Distribution'!H9 -> 0 | D8: ='Current Distribution with Roth'!I9-'Current Distribution'!I9 -> 0 | E8: ='Current Distribution with Roth'!J9-'Current Distribution'!J9 -> 0 | F8: ='Current Distribution with Roth'!K9-'Current Distribution'!K9 -> 0 | G8: ='Current Distribution with Roth'!L9-'Current Distribution'!L9 -> 0 | H8: ='Current Distribution with Roth'!M9-'Current Distribution'!M9 -> 0 | I8: ='Current Distribution with Roth'!N9-'Current Distribution'!N9 -> 0 | J8: ='Current Distribution with Roth'!O9-'Current Distribution'!O9 -> 0 | ... AD8: ='Current Distribution with Roth'!AI9-'Current Distribution'!AI9 -> 0
A9: Susan's Pension | C9: ='Current Distribution with Roth'!H10-'Current Distribution'!H10 -> 0 | D9: ='Current Distribution with Roth'!I10-'Current Distribution'!I10 -> 0 | E9: ='Current Distribution with Roth'!J10-'Current Distribution'!J10 -> 0 | F9: ='Current Distribution with Roth'!K10-'Current Distribution'!K10 -> 0 | G9: ='Current Distribution with Roth'!L10-'Current Distribution'!L10 -> 0 | H9: ='Current Distribution with Roth'!M10-'Current Distribution'!M10 -> 0 | I9: ='Current Distribution with Roth'!N10-'Current Distribution'!N10 -> 0 | J9: ='Current Distribution with Roth'!O10-'Current Distribution'!O10 -> 0 | ... AD9: ='Current Distribution with Roth'!AI10-'Current Distribution'!AI10 -> 0
A10: Susan's Social Security | C10: ='Current Distribution with Roth'!H11-'Current Distribution'!H11 -> 0 | D10: ='Current Distribution with Roth'!I11-'Current Distribution'!I11 -> 0 | E10: ='Current Distribution with Roth'!J11-'Current Distribution'!J11 -> 0 | F10: ='Current Distribution with Roth'!K11-'Current Distribution'!K11 -> 0 | G10: ='Current Distribution with Roth'!L11-'Current Distribution'!L11 -> 0 | H10: ='Current Distribution with Roth'!M11-'Current Distribution'!M11 -> 0 | I10: ='Current Distribution with Roth'!N11-'Current Distribution'!N11 -> 0 | J10: ='Current Distribution with Roth'!O11-'Current Distribution'!O11 -> 0 | ... AD10: ='Current Distribution with Roth'!AI11-'Current Distribution'!AI11 -> 0
A11: Bob's Social Security | C11: ='Current Distribution with Roth'!H12-'Current Distribution'!H12 -> 0 | D11: ='Current Distribution with Roth'!I12-'Current Distribution'!I12 -> 0 | E11: ='Current Distribution with Roth'!J12-'Current Distribution'!J12 -> 0 | F11: ='Current Distribution with Roth'!K12-'Current Distribution'!K12 -> 0 | G11: ='Current Distribution with Roth'!L12-'Current Distribution'!L12 -> 0 | H11: ='Current Distribution with Roth'!M12-'Current Distribution'!M12 -> 0 | I11: ='Current Distribution with Roth'!N12-'Current Distribution'!N12 -> 0 | J11: ='Current Distribution with Roth'!O12-'Current Distribution'!O12 -> 0 | ... AD11: ='Current Distribution with Roth'!AI12-'Current Distribution'!AI12 -> 0
A12: Susan's IRA | C12: ='Current Distribution with Roth'!H13-'Current Distribution'!H13 -> 0 | D12: ='Current Distribution with Roth'!I13-'Current Distribution'!I13 -> 0 | E12: ='Current Distribution with Roth'!J13-'Current Distribution'!J13 -> 0 | F12: ='Current Distribution with Roth'!K13-'Current Distribution'!K13 -> 0 | G12: ='Current Distribution with Roth'!L13-'Current Distribution'!L13 -> 0 | H12: ='Current Distribution with Roth'!M13-'Current Distribution'!M13 -> 0 | I12: ='Current Distribution with Roth'!N13-'Current Distribution'!N13 -> 0 | J12: ='Current Distribution with Roth'!O13-'Current Distribution'!O13 -> 0 | ... AD12: ='Current Distribution with Roth'!AI13-'Current Distribution'!AI13 -> 0
A13: Bob's IRA | C13: ='Current Distribution with Roth'!H15-'Current Distribution'!H15 -> 0 | D13: ='Current Distribution with Roth'!I15-'Current Distribution'!I15 -> 0 | E13: ='Current Distribution with Roth'!J15-'Current Distribution'!J15 -> 0 | F13: ='Current Distribution with Roth'!K15-'Current Distribution'!K15 -> 190743.67 | G13: ='Current Distribution with Roth'!L15-'Current Distribution'!L15 -> 191273.75 | H13: ='Current Distribution with Roth'!M15-'Current Distribution'!M15 -> 192363.74 | I13: ='Current Distribution with Roth'!N15-'Current Distribution'!N15 -> 193753.31 | J13: ='Current Distribution with Roth'!O15-'Current Distribution'!O15 -> 195633.61 | ... AD13: ='Current Distribution with Roth'!AI15-'Current Distribution'!AI15 -> -139203.57
A14: Bob's Roth | C14: ='Current Distribution with Roth'!H16-'Current Distribution'!H16 -> 0 | D14: ='Current Distribution with Roth'!I16-'Current Distribution'!I16 -> 0 | E14: ='Current Distribution with Roth'!J16-'Current Distribution'!J16 -> 0 | F14: ='Current Distribution with Roth'!K16-'Current Distribution'!K16 -> 0 | G14: ='Current Distribution with Roth'!L16-'Current Distribution'!L16 -> 0 | H14: ='Current Distribution with Roth'!M16-'Current Distribution'!M16 -> 0 | I14: ='Current Distribution with Roth'!N16-'Current Distribution'!N16 -> 0 | J14: ='Current Distribution with Roth'!O16-'Current Distribution'!O16 -> 0 | ... AD14: ='Current Distribution with Roth'!AI16-'Current Distribution'!AI16 -> 0
